[MFLOG|0|2022-12-05T21:32:48.880153Z|runtime|5a766eaa-90a5-4860-8a79-07c398215bf2]<flow MyClassificationFlow step load_pos_neg_words> failed:
[MFLOG|0|2022-12-05T21:32:48.884518Z|runtime|c1d0306a-4674-4bc3-9320-48adf703ecc7]    Internal error
[MFLOG|0|2022-12-05T21:32:48.885899Z|runtime|a5a7752b-16d7-4d6d-a452-02fdcf293102]Traceback (most recent call last):
[MFLOG|0|2022-12-05T21:32:48.885983Z|runtime|02f65618-4a5a-4cac-858f-9f84c76156b8]  File "/Users/lyric/opt/anaconda3/envs/mlsys/lib/python3.9/site-packages/metaflow/cli.py", line 1171, in main
[MFLOG|0|2022-12-05T21:32:48.886051Z|runtime|b715a15b-9b9c-420a-b72e-f76375851af8]    start(auto_envvar_prefix="METAFLOW", obj=state)
[MFLOG|0|2022-12-05T21:32:48.886100Z|runtime|9b450ebe-ae97-4471-b680-43285a81988c]  File "/Users/lyric/opt/anaconda3/envs/mlsys/lib/python3.9/site-packages/metaflow/_vendor/click/core.py", line 829, in __call__
[MFLOG|0|2022-12-05T21:32:48.886155Z|runtime|b7e11950-04f4-471c-aa9e-04c4c6ec3133]    return self.main(args, kwargs)
[MFLOG|0|2022-12-05T21:32:49.172561Z|runtime|81b8384d-8494-4d06-a688-4a455d99b3f3]  File "/Users/lyric/opt/anaconda3/envs/mlsys/lib/python3.9/site-packages/metaflow/_vendor/click/core.py", line 782, in main
[MFLOG|0|2022-12-05T21:32:49.172820Z|runtime|a722a350-aa55-4f8b-8c4e-e966ad81be6a]    rv = self.invoke(ctx)
[MFLOG|0|2022-12-05T21:32:49.172887Z|runtime|d5105ec6-e11e-4c2c-b9f6-a0a4360ba991]  File "/Users/lyric/opt/anaconda3/envs/mlsys/lib/python3.9/site-packages/metaflow/_vendor/click/core.py", line 1259, in invoke
[MFLOG|0|2022-12-05T21:32:49.172934Z|runtime|01035803-087f-4b57-aa6f-800a4980aa51]    return _process_result(sub_ctx.command.invoke(sub_ctx))
[MFLOG|0|2022-12-05T21:32:49.172978Z|runtime|169d5b1a-dea4-4461-9fed-5df01ab720c0]  File "/Users/lyric/opt/anaconda3/envs/mlsys/lib/python3.9/site-packages/metaflow/_vendor/click/core.py", line 1066, in invoke
[MFLOG|0|2022-12-05T21:32:49.173018Z|runtime|d1c281ac-292a-4f61-818c-e23fe45ceed1]    return ctx.invoke(self.callback, ctx.params)
[MFLOG|0|2022-12-05T21:32:49.173058Z|runtime|de965f5c-57d3-4098-b9c9-c40ca7354b31]  File "/Users/lyric/opt/anaconda3/envs/mlsys/lib/python3.9/site-packages/metaflow/_vendor/click/core.py", line 610, in invoke
[MFLOG|0|2022-12-05T21:32:49.173097Z|runtime|04d29941-0353-4123-a731-b3841c27456c]    return callback(args, kwargs)
[MFLOG|0|2022-12-05T21:32:49.173137Z|runtime|6814f91f-b98d-4ccb-9edf-ff03b83fbb9c]  File "/Users/lyric/opt/anaconda3/envs/mlsys/lib/python3.9/site-packages/metaflow/_vendor/click/decorators.py", line 21, in new_func
[MFLOG|0|2022-12-05T21:32:49.173175Z|runtime|9ca8871e-0633-4ab3-aac3-f7fc6117e1f7]    return f(get_current_context(), args, kwargs)
[MFLOG|0|2022-12-05T21:32:49.173213Z|runtime|571bd0ca-9984-4866-a26b-f49ab2e2b5bc]  File "/Users/lyric/opt/anaconda3/envs/mlsys/lib/python3.9/site-packages/metaflow/cli.py", line 580, in step
[MFLOG|0|2022-12-05T21:32:49.173250Z|runtime|c2c51134-67c4-49e6-86be-4b3cf523e731]    task.run_step(
[MFLOG|0|2022-12-05T21:32:49.173287Z|runtime|fa724072-567b-46f5-83ed-6acc85b69a79]  File "/Users/lyric/opt/anaconda3/envs/mlsys/lib/python3.9/site-packages/metaflow/task.py", line 587, in run_step
[MFLOG|0|2022-12-05T21:32:49.173324Z|runtime|9876cecb-d914-48e4-a203-0496b8fffca1]    self._exec_step_function(step_func)
[MFLOG|0|2022-12-05T21:32:49.173363Z|runtime|0f707705-3a45-46cf-b85a-b7dbe3e65fb8]  File "/Users/lyric/opt/anaconda3/envs/mlsys/lib/python3.9/site-packages/metaflow/task.py", line 61, in _exec_step_function
[MFLOG|0|2022-12-05T21:32:49.173401Z|runtime|ca8a2555-4dc8-473d-b893-15a957e3ad94]    step_function()
[MFLOG|0|2022-12-05T21:32:49.173438Z|runtime|4027ed3a-3e4a-4c28-9585-63a1e48d26b9]  File "/Users/lyric/Dropbox/Code/MLSys-Final/tmp/final.py", line 283, in load_pos_neg_words
[MFLOG|0|2022-12-05T21:32:49.173475Z|runtime|b3bdfb58-9f19-44fe-884f-1152563760b1]    with open('./positive.txt','r') as p:
[MFLOG|0|2022-12-05T21:32:49.173513Z|runtime|957a5bbf-57ff-47b6-8177-c358852f28ec]FileNotFoundError: [Errno 2] No such file or directory: './positive.txt'
[MFLOG|0|2022-12-05T21:32:49.173558Z|runtime|9cfaf7ba-5d38-4169-9915-7a24fa60c4dd]
[MFLOG|0|2022-12-05T21:32:49.174093Z|runtime|a4a4605f-f799-4f97-b3ab-6fcbb6cf029b]Task failed.