[MFLOG|0|2022-12-05T21:55:09.111278Z|runtime|e5797bba-fa22-4e6b-90bd-c23184c32aee]<flow MyClassificationFlow step load_pos_neg_words> failed:
[MFLOG|0|2022-12-05T21:55:09.116075Z|runtime|30a4b7f7-62b6-4087-ba4a-f8c569d794e0]    Internal error
[MFLOG|0|2022-12-05T21:55:09.116743Z|runtime|83e4f707-fda0-41d6-987f-ab7383a32160]Traceback (most recent call last):
[MFLOG|0|2022-12-05T21:55:09.116812Z|runtime|4bc0591f-08e0-4baf-b81e-274db13dd2aa]  File "/Users/lyric/opt/anaconda3/envs/mlsys/lib/python3.9/site-packages/metaflow/cli.py", line 1171, in main
[MFLOG|0|2022-12-05T21:55:09.116881Z|runtime|5da23c99-ed65-4bbf-b755-6ab939cdeb18]    start(auto_envvar_prefix="METAFLOW", obj=state)
[MFLOG|0|2022-12-05T21:55:09.116951Z|runtime|4fd18027-e486-42a1-b743-7ff976a80b4d]  File "/Users/lyric/opt/anaconda3/envs/mlsys/lib/python3.9/site-packages/metaflow/_vendor/click/core.py", line 829, in __call__
[MFLOG|0|2022-12-05T21:55:09.117006Z|runtime|e0c6f3be-d4f3-442b-adf6-b165a8a59cb2]    return self.main(args, kwargs)
[MFLOG|0|2022-12-05T21:55:09.117056Z|runtime|e10fff73-d28f-4c8a-a5db-14088dd2332b]  File "/Users/lyric/opt/anaconda3/envs/mlsys/lib/python3.9/site-packages/metaflow/_vendor/click/core.py", line 782, in main
[MFLOG|0|2022-12-05T21:55:09.117101Z|runtime|c056d97c-e16e-41db-8916-89c3c8758da7]    rv = self.invoke(ctx)
[MFLOG|0|2022-12-05T21:55:09.117145Z|runtime|52e41e9f-a967-42f5-ba3d-86eb55635cd7]  File "/Users/lyric/opt/anaconda3/envs/mlsys/lib/python3.9/site-packages/metaflow/_vendor/click/core.py", line 1259, in invoke
[MFLOG|0|2022-12-05T21:55:09.117188Z|runtime|23b00770-dacf-4105-94b7-1fe28c41e546]    return _process_result(sub_ctx.command.invoke(sub_ctx))
[MFLOG|0|2022-12-05T21:55:09.117230Z|runtime|8364ad21-b5fb-4df1-8191-38c972c675bf]  File "/Users/lyric/opt/anaconda3/envs/mlsys/lib/python3.9/site-packages/metaflow/_vendor/click/core.py", line 1066, in invoke
[MFLOG|0|2022-12-05T21:55:09.117280Z|runtime|a5e55e2f-5041-4b17-9b94-aafbd793302c]    return ctx.invoke(self.callback, ctx.params)
[MFLOG|0|2022-12-05T21:55:09.117322Z|runtime|fdb4b49a-9763-4365-84a1-93b9c0cd41eb]  File "/Users/lyric/opt/anaconda3/envs/mlsys/lib/python3.9/site-packages/metaflow/_vendor/click/core.py", line 610, in invoke
[MFLOG|0|2022-12-05T21:55:09.117366Z|runtime|fa7db00e-1cfa-4fdb-a5cc-ad9853949515]    return callback(args, kwargs)
[MFLOG|0|2022-12-05T21:55:09.403138Z|runtime|4c37a93f-cfdb-4d76-9d4e-f450bd1e4328]  File "/Users/lyric/opt/anaconda3/envs/mlsys/lib/python3.9/site-packages/metaflow/_vendor/click/decorators.py", line 21, in new_func
[MFLOG|0|2022-12-05T21:55:09.403391Z|runtime|62b9e7ee-e751-4c4e-8dd9-d3de7a48e6c8]    return f(get_current_context(), args, kwargs)
[MFLOG|0|2022-12-05T21:55:09.403452Z|runtime|3560b9f5-23a7-4fea-a69e-553d4d637db5]  File "/Users/lyric/opt/anaconda3/envs/mlsys/lib/python3.9/site-packages/metaflow/cli.py", line 580, in step
[MFLOG|0|2022-12-05T21:55:09.403497Z|runtime|0ab145a4-032e-4fc7-a6a6-beebd3402479]    task.run_step(
[MFLOG|0|2022-12-05T21:55:09.403539Z|runtime|86fa23bb-72e9-451d-87ea-1e3985419f33]  File "/Users/lyric/opt/anaconda3/envs/mlsys/lib/python3.9/site-packages/metaflow/task.py", line 587, in run_step
[MFLOG|0|2022-12-05T21:55:09.403578Z|runtime|24a421c4-3b47-4ae4-9cf4-f097374a331e]    self._exec_step_function(step_func)
[MFLOG|0|2022-12-05T21:55:09.403617Z|runtime|e8353110-3ff8-45da-bdf7-607d67a779ad]  File "/Users/lyric/opt/anaconda3/envs/mlsys/lib/python3.9/site-packages/metaflow/task.py", line 61, in _exec_step_function
[MFLOG|0|2022-12-05T21:55:09.403660Z|runtime|3e4909df-e9f1-4f75-8fea-d84a7d350d2a]    step_function()
[MFLOG|0|2022-12-05T21:55:09.403774Z|runtime|2a0de782-4e3d-442b-a218-9f6c106d25f7]  File "/Users/lyric/Dropbox/Code/MLSys-Final/tmp/final.py", line 296, in load_pos_neg_words
[MFLOG|0|2022-12-05T21:55:09.403826Z|runtime|4ca88f81-5f98-4269-ac2b-7337af25951f]    for nline in n:
[MFLOG|0|2022-12-05T21:55:09.403873Z|runtime|d20045a8-4255-4e4e-9e82-eba0b05e36d1]  File "/Users/lyric/opt/anaconda3/envs/mlsys/lib/python3.9/codecs.py", line 322, in decode
[MFLOG|0|2022-12-05T21:55:09.404033Z|runtime|4ddd064d-c2c1-43f1-8b92-9f9c989a194c]    (result, consumed) = self._buffer_decode(data, self.errors, final)
[MFLOG|0|2022-12-05T21:55:09.404193Z|runtime|3d3e1334-c206-4e06-a809-e6a845c28610]UnicodeDecodeError: 'utf-8' codec can't decode byte 0xef in position 6977: invalid continuation byte
[MFLOG|0|2022-12-05T21:55:09.404249Z|runtime|53a05727-b4fb-498d-ac67-ea0213ac4951]
[MFLOG|0|2022-12-05T21:55:09.404726Z|runtime|110f93e4-cd87-421f-9a00-0efde2df2890]Task failed.